<sdf version='1.6'>
  <model name='gripper2'>
    <link name='base_link'>
      <pose frame=''>0 0 0 0 -0 0</pose>
      <inertial>
        <pose frame=''>-0.008569 -0.00331 -7.8e-05 0 -0 0</pose>
        <mass>0.11906</mass>
        <inertia>
          <ixx>5.4401e-05</ixx>
          <ixy>-3.727e-07</ixy>
          <ixz>-2.0098e-07</ixz>
          <iyy>2.8843e-05</iyy>
          <iyz>-6.0295e-07</iyz>
          <izz>3.7188e-05</izz>
        </inertia>
      </inertial>
      <collision name='base_link_collision'>
        <pose frame=''>0 0 0 0 -0 0</pose>
        <geometry>
          <mesh>
            <scale>1 1 1</scale>
            <uri>model://gripper2/meshes/base_link.STL</uri>
          </mesh>
        </geometry>
      </collision>
      <visual name='base_link_visual'>
        <pose frame=''>0 0 0 0 -0 0</pose>
        <geometry>
          <mesh>
            <scale>1 1 1</scale>
            <uri>model://gripper2/meshes/base_link.STL</uri>
          </mesh>
        </geometry>
      </visual>
    </link>
    <link name='left_link'>
      <pose frame=''>-0.0135 0 0.01 0 -0 0</pose>
      <inertial>
        <pose frame=''>-0.059051 -0.002195 0.020051 0 -0 0</pose>
        <mass>0.026471</mass>
        <inertia>
          <ixx>1.3813e-06</ixx>
          <ixy>-1.211e-11</ixy>
          <ixz>1.2469e-06</ixz>
          <iyy>7.2157e-06</iyy>
          <iyz>-9.8817e-12</iyz>
          <izz>7.1751e-06</izz>
        </inertia>
      </inertial>
      <collision name='left_link_collision'>
        <pose frame=''>0 0 0 0 -0 0</pose>
        <geometry>
          <mesh>
            <scale>1 1 1</scale>
            <uri>model://gripper2/meshes/left_link.STL</uri>
          </mesh>
        </geometry>
      </collision>
      <visual name='left_link_visual'>
        <pose frame=''>0 0 0 0 -0 0</pose>
        <geometry>
          <mesh>
            <scale>1 1 1</scale>
            <uri>model://gripper2/meshes/left_link.STL</uri>
          </mesh>
        </geometry>
      </visual>
    </link>
    <joint name='left_joint' type='revolute'>
      <child>left_link</child>
      <parent>base_link</parent>
      <axis>
        <xyz>0 -1 0.5</xyz>
        <limit>
          <lower>-3</lower>
          <upper>3</upper>
          <effort>1</effort>
          <velocity>1</velocity>
        </limit>
        <dynamics>
          <spring_reference>0</spring_reference>
          <spring_stiffness>0</spring_stiffness>
        </dynamics>
        <use_parent_model_frame>0</use_parent_model_frame>
      </axis>
    </joint>
    <link name='right_link'>
      <pose frame=''>-0.0135 0 -0.014 0 -0 0</pose>
      <inertial>
        <pose frame=''>-0.060951 -0.003321 -0.004856 0 -0 0</pose>
        <mass>0.027594</mass>
        <inertia>
          <ixx>1.2215e-06</ixx>
          <ixy>5.8021e-12</ixy>
          <ixz>1.3138e-07</ixz>
          <iyy>9.4165e-06</iyy>
          <iyz>-7.6154e-12</iyz>
          <izz>9.537e-06</izz>
        </inertia>
      </inertial>
      <collision name='right_link_collision'>
        <pose frame=''>0 0 0 0 -0 0</pose>
        <geometry>
          <mesh>
            <scale>1 1 1</scale>
            <uri>model://gripper2/meshes/right_link.STL</uri>
          </mesh>
        </geometry>
      </collision>
      <visual name='right_link_visual'>
        <pose frame=''>0 0 0 0 -0 0</pose>
        <geometry>
          <mesh>
            <scale>1 1 1</scale>
            <uri>model://gripper2/meshes/right_link.STL</uri>
          </mesh>
        </geometry>
      </visual>
    </link>
    <joint name='right_joint' type='revolute'>
      <child>right_link</child>
      <parent>base_link</parent>
      <axis>
        <xyz>0 -1 0.5</xyz>
        <limit>
          <lower>-3</lower>
          <upper>3</upper>
          <effort>1</effort>
          <velocity>1</velocity>
        </limit>
        <dynamics>
          <spring_reference>0</spring_reference>
          <spring_stiffness>0</spring_stiffness>
        </dynamics>
        <use_parent_model_frame>0</use_parent_model_frame>
      </axis>
    </joint>
  <plugin name="gripper_control2_1" filename="libgripper_plugin2_1.so"/>
  <plugin name="gripper_control2_2" filename="libgripper_plugin2_2.so"/>
  </model>
</sdf>
