<sdf version='1.6'>
  <model name='gripper2'>
    <link name='base_link'>
      <pose frame=''>0 0 0 0 -0 0</pose>
      <inertial>
        <pose frame=''>-0.008431 -0.002651 -0.000156 0 -0 0</pose>
        <mass>0.11581</mass>
        <inertia>
          <ixx>5.4342e-05</ixx>
          <ixy>-3.727e-07</ixy>
          <ixz>-2.0098e-07</ixz>
          <iyy>2.8746e-05</iyy>
          <iyz>-6.0295e-07</iyz>
          <izz>3.713e-05</izz>
        </inertia>
      </inertial>
      <collision name='base_link_collision'>
        <pose frame=''>0 0 0 0 -0 0</pose>
        <geometry>
          <mesh>
            <scale>1 1 1</scale>
            <uri>model://gripper2/meshes/base_link.STL</uri>
          </mesh>
        </geometry>
      </collision>
      <visual name='base_link_visual'>
        <pose frame=''>0 0 0 0 -0 0</pose>
        <geometry>
          <mesh>
            <scale>1 1 1</scale>
            <uri>model://gripper2/meshes/base_link.STL</uri>
          </mesh>
        </geometry>
      </visual>
    </link>
    <link name='gripper_1'>
      <pose frame=''>-0.0135 0.031 0.01 0 -0 0</pose>
      <inertial>
        <pose frame=''>-0.050044 -0.036247 0.009818 0 -0 0</pose>
        <mass>0.03309</mass>
        <inertia>
          <ixx>1.3776e-06</ixx>
          <ixy>-1.0234e-11</ixy>
          <ixz>7.8971e-07</ixz>
          <iyy>9.3255e-06</iyy>
          <iyz>-5.4425e-12</iyz>
          <izz>9.3392e-06</izz>
        </inertia>
      </inertial>
      <collision name='gripper_1_collision'>
        <pose frame=''>0 0 0 0 -0 0</pose>
        <geometry>
          <mesh>
            <scale>1 1 1</scale>
            <uri>model://gripper2/meshes/gripper_1.STL</uri>
          </mesh>
        </geometry>
      </collision>
      <visual name='gripper_1_visual'>
        <pose frame=''>0 0 0 0 -0 0</pose>
        <geometry>
          <mesh>
            <scale>1 1 1</scale>
            <uri>model://gripper2/meshes/gripper_1.STL</uri>
          </mesh>
        </geometry>
      </visual>
    </link>
    <joint name='gripper_joint1' type='revolute'>
      <child>gripper_1</child>
      <parent>base_link</parent>
      <axis>
        <xyz>0 -1 0</xyz>
        <limit>
          <lower>-10</lower>
          <upper>10</upper>
          <effort>1</effort>
          <velocity>0</velocity>
        </limit>
        <dynamics>
          <spring_reference>0</spring_reference>
          <spring_stiffness>0</spring_stiffness>
        </dynamics>
        <use_parent_model_frame>0</use_parent_model_frame>
      </axis>
    </joint>
    <link name='gripper_2'>
      <pose frame=''>-0.0135 0.031 -0.014 0 -0 0</pose>
      <inertial>
        <pose frame=''>-0.044918 -0.034439 -0.031837 0 -0 0</pose>
        <mass>0.030645</mass>
        <inertia>
          <ixx>3.3093e-06</ixx>
          <ixy>8.5572e-12</ixy>
          <ixz>-3.5932e-06</ixz>
          <iyy>9.4278e-06</iyy>
          <iyz>-3.295e-12</iyz>
          <izz>7.5029e-06</izz>
        </inertia>
      </inertial>
      <collision name='gripper_2_collision'>
        <pose frame=''>0 0 0 0 -0 0</pose>
        <geometry>
          <mesh>
            <scale>1 1 1</scale>
            <uri>model://gripper2/meshes/gripper_2.STL</uri>
          </mesh>
        </geometry>
      </collision>
      <visual name='gripper_2_visual'>
        <pose frame=''>0 0 0 0 -0 0</pose>
        <geometry>
          <mesh>
            <scale>1 1 1</scale>
            <uri>model://gripper2/meshes/gripper_2.STL</uri>
          </mesh>
        </geometry>
      </visual>
    </link>
    <joint name='gripper_joint2' type='revolute'>
      <child>gripper_2</child>
      <parent>base_link</parent>
      <axis>
        <xyz>0 -1 0</xyz>
        <limit>
          <lower>-10</lower>
          <upper>10</upper>
          <effort>0</effort>
          <velocity>0</velocity>
        </limit>
        <dynamics>
          <spring_reference>0</spring_reference>
          <spring_stiffness>0</spring_stiffness>
        </dynamics>
        <use_parent_model_frame>0</use_parent_model_frame>
      </axis>
    </joint>
    <plugin name="gripper_control1" filename="libgripper_plugin1.so"/>
    <plugin name="gripper_control2" filename="libgripper_plugin2.so"/>
  </model>
</sdf>
