<sdf version='1.6'>
  <model name='gripper2'>
    <link name='base_link'>
      <pose frame=''>0 0 0 0 -0 0</pose>
      <inertial>
        <pose frame=''>-0.008431 -0.002651 -0.000156 0 -0 0</pose>
        <mass>0.11581</mass>
        <inertia>
          <ixx>5.4342e-05</ixx>
          <ixy>-3.727e-07</ixy>
          <ixz>-2.0098e-07</ixz>
          <iyy>2.8746e-05</iyy>
          <iyz>-6.0295e-07</iyz>
          <izz>3.713e-05</izz>
        </inertia>
      </inertial>
      <collision name='base_link_collision'>
        <pose frame=''>0 0 0 0 -0 0</pose>
        <geometry>
          <mesh>
            <scale>1 1 1</scale>
            <uri>model://gripper2/meshes/base_link.STL</uri>
          </mesh>
        </geometry>
      </collision>
      <visual name='base_link_visual'>
        <pose frame=''>0 0 0 0 -0 0</pose>
        <geometry>
          <mesh>
            <scale>1 1 1</scale>
            <uri>model://gripper2/meshes/base_link.STL</uri>
          </mesh>
        </geometry>
      </visual>
    </link>
    <link name='left_link'>
      <pose frame=''>-0.0135 0.024 -0.014 0 -0 0</pose>
      <inertial>
        <pose frame=''>-0.046709 -0.027439 -0.029147 0 -0 0</pose>
        <mass>0.030645</mass>
        <inertia>
          <ixx>2.9028e-06</ixx>
          <ixy>8.3629e-12</ixy>
          <ixz>-3.3228e-06</ixz>
          <iyy>9.4277e-06</iyy>
          <iyz>-3.8595e-12</iyz>
          <izz>7.9093e-06</izz>
        </inertia>
      </inertial>
      <collision name='left_link_collision'>
        <pose frame=''>0 0 0 0 -0 0</pose>
        <geometry>
          <mesh>
            <scale>1 1 1</scale>
            <uri>model://gripper2/meshes/left_link.STL</uri>
          </mesh>
        </geometry>
      </collision>
      <visual name='left_link_visual'>
        <pose frame=''>0 0 0 0 -0 0</pose>
        <geometry>
          <mesh>
            <scale>1 1 1</scale>
            <uri>model://gripper2/meshes/left_link.STL</uri>
          </mesh>
        </geometry>
      </visual>
    </link>
    <joint name='left_joint' type='revolute'>
      <child>left_link</child>
      <parent>base_link</parent>
      <axis>
        <xyz>0 1 0</xyz>
        <limit>
          <lower>0</lower>
          <upper>0</upper>
          <effort>0</effort>
          <velocity>0</velocity>
        </limit>
        <dynamics>
          <spring_reference>0</spring_reference>
          <spring_stiffness>0</spring_stiffness>
        </dynamics>
        <use_parent_model_frame>0</use_parent_model_frame>
      </axis>
    </joint>
    <link name='right_link'>
      <pose frame=''>-0.0135 0.024 0.01 0 -0 0</pose>
      <inertial>
        <pose frame=''>-0.046301 -0.029247 0.021379 0 -0 0</pose>
        <mass>0.03309</mass>
        <inertia>
          <ixx>2.1863e-06</ixx>
          <ixy>-1.0959e-11</ixy>
          <ixz>2.5315e-06</ixz>
          <iyy>9.3261e-06</iyy>
          <iyz>-2.3809e-12</iyz>
          <izz>8.531e-06</izz>
        </inertia>
      </inertial>
      <collision name='right_link_collision'>
        <pose frame=''>0 0 0 0 -0 0</pose>
        <geometry>
          <mesh>
            <scale>1 1 1</scale>
            <uri>model://gripper2/meshes/right_link.STL</uri>
          </mesh>
        </geometry>
      </collision>
      <visual name='right_link_visual'>
        <pose frame=''>0 0 0 0 -0 0</pose>
        <geometry>
          <mesh>
            <scale>1 1 1</scale>
            <uri>model://gripper2/meshes/right_link.STL</uri>
          </mesh>
        </geometry>
      </visual>
    </link>
    <joint name='right_joint' type='revolute'>
      <child>right_link</child>
      <parent>base_link</parent>
      <axis>
        <xyz>0 -1 0</xyz>
        <limit>
          <lower>-10</lower>
          <upper>10</upper>
          <effort>10</effort>
          <velocity>1</velocity>
        </limit>
        <dynamics>
          <spring_reference>0</spring_reference>
          <spring_stiffness>0</spring_stiffness>
        </dynamics>
        <use_parent_model_frame>0</use_parent_model_frame>
      </axis>
    </joint>
  <plugin name="gripper_control1" filename="libgripper_plugin1.so"/>
  </model>
</sdf>
