<?xml version="1.0" encoding="utf-8"?>
<!-- This URDF was automatically created by SolidWorks to URDF Exporter! Originally created by Stephen Brawner (brawner@gmail.com) 
     Commit Version: 1.6.0-4-g7f85cfe  Build Version: 1.6.7995.38578
     For more information, please see http://wiki.ros.org/sw_urdf_exporter -->
<robot
  name="gripper1">
  <link
    name="base_link">
    <inertial>
      <origin
        xyz="0.0013614 -0.029606 -0.00022964"
        rpy="0 0 0" />
      <mass
        value="0.18394" />
      <inertia
        ixx="4.1667E-05"
        ixy="2.8477E-07"
        ixz="2.6891E-08"
        iyy="0.00011208"
        iyz="-6.7446E-07"
        izz="0.00014361" />
    </inertial>
    <visual>
      <origin
        xyz="0 0 0"
        rpy="0 0 0" />
      <geometry>
        <mesh
          filename="package://gripper1/meshes/base_link.STL" />
      </geometry>
      <material
        name="">
        <color
          rgba="0.75294 0.75294 0.75294 1" />
      </material>
    </visual>
    <collision>
      <origin
        xyz="0 0 0"
        rpy="0 0 0" />
      <geometry>
        <mesh
          filename="package://gripper1/meshes/base_link.STL" />
      </geometry>
    </collision>
  </link>
  <link
    name="left_link">
    <inertial>
      <origin
        xyz="0.036311 -0.0093129 0.0019175"
        rpy="0 0 0" />
      <mass
        value="0.19697" />
      <inertia
        ixx="5.6663E-05"
        ixy="1.6094E-20"
        ixz="4.2352E-22"
        iyy="2.3404E-05"
        iyz="-6.7051E-06"
        izz="5.7287E-05" />
    </inertial>
    <visual>
      <origin
        xyz="0 0 0"
        rpy="0 0 0" />
      <geometry>
        <mesh
          filename="package://gripper1/meshes/left_link.STL" />
      </geometry>
      <material
        name="">
        <color
          rgba="0.75294 0.75294 0.75294 1" />
      </material>
    </visual>
    <collision>
      <origin
        xyz="0 0 0"
        rpy="0 0 0" />
      <geometry>
        <mesh
          filename="package://gripper1/meshes/left_link.STL" />
      </geometry>
    </collision>
  </link>
  <joint
    name="left_joint"
    type="prismatic">
    <origin
      xyz="-0.051103 -0.052 0.0005"
      rpy="0 0 0" />
    <parent
      link="base_link" />
    <child
      link="left_link" />
    <axis
      xyz="-1 0 0" />
    <limit
      lower="-0.05"
      upper="0.05"
      effort="1"
      velocity="0.1" />
  </joint>
  <link
    name="right_link">
    <inertial>
      <origin
        xyz="0.015639 -0.005269 -0.0019301"
        rpy="0 0 0" />
      <mass
        value="0.098607" />
      <inertia
        ixx="2.8497E-05"
        ixy="4.6686E-06"
        ixz="-4.0714E-07"
        iyy="1.1715E-05"
        iyz="3.3961E-06"
        izz="2.8797E-05" />
    </inertial>
    <visual>
      <origin
        xyz="0 0 0"
        rpy="0 0 0" />
      <geometry>
        <mesh
          filename="package://gripper1/meshes/right_link.STL" />
      </geometry>
      <material
        name="">
        <color
          rgba="0.75294 0.75294 0.75294 1" />
      </material>
    </visual>
    <collision>
      <origin
        xyz="0 0 0"
        rpy="0 0 0" />
      <geometry>
        <mesh
          filename="package://gripper1/meshes/right_link.STL" />
      </geometry>
    </collision>
  </link>
  <joint
    name="right_joint"
    type="prismatic">
    <origin
      xyz="0.037773 -0.056 0.0005"
      rpy="3.1416 0 3.1416" />
    <parent
      link="base_link" />
    <child
      link="right_link" />
    <axis
      xyz="1 0 0" />
    <limit
      lower="-0.05"
      upper="0.05"
      effort="1"
      velocity="0.1" />
  </joint>
</robot>