<sdf version='1.6'>
  <model name='gripper1'>
    <link name='base_link'>
      <pose frame=''>0 0 0 0 -0 0</pose>
      <inertial>
        <pose frame=''>0.001361 -0.029606 -0.00023 0 -0 0</pose>
        <mass>0.1</mass>
        <inertia>
          <ixx>4.1667e-05</ixx>
          <ixy>2.8477e-07</ixy>
          <ixz>2.6891e-08</ixz>
          <iyy>0.00011208</iyy>
          <iyz>-6.7446e-07</iyz>
          <izz>0.00014361</izz>
        </inertia>
      </inertial>
      <collision name='base_link_collision'>
        <pose frame=''>0 0 0 0 -0 0</pose>
        <geometry>
          <mesh>
            <scale>1 1 1</scale>
            <uri>model://gripper1/meshes/base_link.STL</uri>
          </mesh>
        </geometry>
      </collision>
      <visual name='base_link_visual'>
        <pose frame=''>0 0 0 0 -0 0</pose>
        <geometry>
          <mesh>
            <scale>1 1 1</scale>
            <uri>model://gripper1/meshes/base_link.STL</uri>
          </mesh>
        </geometry>
      </visual>
    </link>
    <link name='left_link'>
      <pose frame=''>-0.06 -0.052 0.0005 0 -0 0</pose>
      <inertial>
        <pose frame=''>0.036311 -0.009313 0.001918 0 -0 0</pose>
        <mass>0.1</mass>
        <inertia>
          <ixx>5.6663e-05</ixx>
          <ixy>1.6094e-20</ixy>
          <ixz>4.2352e-22</ixz>
          <iyy>2.3404e-05</iyy>
          <iyz>-6.7051e-06</iyz>
          <izz>5.7287e-05</izz>
        </inertia>
      </inertial>
      <collision name='left_link_collision'>
        <pose frame=''>0 0 0 0 -0 0</pose>
        <geometry>
          <mesh>
            <scale>1 1 1</scale>
            <uri>model://gripper1/meshes/left_link.STL</uri>
          </mesh>
        </geometry>
          <surface>
            <friction>
              <ode>
                <mu>30</mu>
                <mu2>30</mu2>
              </ode>
            </friction>
          </surface>
      </collision>
      <visual name='left_link_visual'>
        <pose frame=''>0 0 0 0 -0 0</pose>
        <geometry>
          <mesh>
            <scale>1 1 1</scale>
            <uri>model://gripper1/meshes/left_link.STL</uri>
          </mesh>
        </geometry>
      </visual>
    </link>
    <joint name='left_joint' type='prismatic'>
      <child>left_link</child>
      <parent>base_link</parent>
      <axis>
        <xyz>-1 0 -0</xyz>
        <limit>
          <lower>-0.025</lower>
          <upper>0</upper>
          <effort>50</effort>
          <velocity>1</velocity>
        </limit>
        <dynamics>
          <spring_reference>0</spring_reference>
          <spring_stiffness>0</spring_stiffness>
      	  <damping>0</damping>
      	  <friction>0.1</friction>
        </dynamics>
        <use_parent_model_frame>0</use_parent_model_frame>
      </axis>
    </joint>
    <link name='right_link'>
      <pose frame=''>0.05 -0.056 0.0005 -3.14159 -0 -3.14159</pose>
      <inertial>
        <pose frame=''>0.015639 -0.005269 -0.00193 0 -0 0</pose>
        <mass>0.1</mass>
        <inertia>
          <ixx>2.8497e-05</ixx>
          <ixy>4.6686e-20</ixy>
          <ixz>-4.0714e-22</ixz>
          <iyy>1.1715e-05</iyy>
          <iyz>3.3961e-06</iyz>
          <izz>2.8797e-05</izz>
        </inertia>
      </inertial>
      <collision name='right_link_collision'>
        <pose frame=''>0 0 0 0 -0 0</pose>
        <geometry>
          <mesh>
            <scale>1 1 1</scale>
            <uri>model://gripper1/meshes/right_link.STL</uri>
          </mesh>
        </geometry>
          <surface>
            <friction>
              <ode>
                <mu>30</mu>
                <mu2>30</mu2>
              </ode>
            </friction>
          </surface>
      </collision>
      <visual name='right_link_visual'>
        <pose frame=''>0 0 0 0 -0 0</pose>
        <geometry>
          <mesh>
            <scale>1 1 1</scale>
            <uri>model://gripper1/meshes/right_link.STL</uri>
          </mesh>
        </geometry>
      </visual>
    </link>
    <joint name='right_joint' type='prismatic'>
      <child>right_link</child>
      <parent>base_link</parent>
      <axis>
        <xyz>1 0 0</xyz>
        <limit>
          <lower>0</lower>
          <upper>0.025</upper>
          <effort>50</effort>
          <velocity>1</velocity>
        </limit>
        <dynamics>
          <spring_reference>0</spring_reference>
          <spring_stiffness>0</spring_stiffness>
      	  <damping>0</damping>
      	  <friction>0.1</friction>
        </dynamics>
        <use_parent_model_frame>0</use_parent_model_frame>
      </axis>
    </joint>
  <plugin name="gripper_control1_1" filename="libgripper_plugin1_1.so"/>
  <plugin name="gripper_control1_2" filename="libgripper_plugin1_2.so"/>
  </model>
</sdf>
