<sdf version='1.6'>
  <model name='gripper3'>
    <link name='base_link'>
      <pose frame=''>0 0 0 0 -0 0</pose>
      <inertial>
        <pose frame=''>0.022563 0.018368 -0.0176 0 -0 0</pose>
        <mass>0.085138</mass>
        <inertia>
          <ixx>1.5815E-05</ixx>
          <ixy>5.4955E-07</ixy>
          <ixz>-7.279E-07</ixz>
          <iyy>2.219E-05</iyy>
          <iyz>2.9639E-06</iyz>
          <izz>2.4841E-05</izz>
        </inertia>
      </inertial>
      <collision name='base_link_collision'>
        <pose frame=''>0 0 0 0 -0 0</pose>
        <geometry>
          <mesh>
            <scale>1 1 1</scale>
            <uri>model://gripper3/meshes/base_link.STL</uri>
          </mesh>
        </geometry>
      </collision>
      <visual name='base_link_visual'>
        <pose frame=''>0 0 0 0 -0 0</pose>
        <geometry>
          <mesh>
            <scale>1 1 1</scale>
            <uri>model://gripper3/meshes/base_link.STL</uri>
          </mesh>
        </geometry>
      </visual>
    </link>
    <link name='Empty_Link1'>
      <pose frame=''>0.04 0 0.02 1.5708 0.90665 -0</pose>
      <inertial>
        <pose frame=''>-0.021122 0.028354 -0.005583 0 -0 0</pose>
        <mass>0.1</mass>
        <inertia>
          <ixx>1.1931E-05</ixx>
          <ixy>8.7376E-06</ixy>
          <ixz>-1.3248E-16</ixz>
          <iyy>8.789E-06</iyy>
          <iyz>-2.1751E-17</iyz>
          <izz>2.0324E-05</izz>
        </inertia>
      </inertial>
      <collision name='Empty_Link1_collision'>
        <pose frame=''>0 0 0 0 -0 0</pose>
        <geometry>
          <mesh>
            <scale>1 1 1</scale>
            <uri>model://gripper3/meshes/Empty_Link1.STL</uri>
          </mesh>
        </geometry>
 <!--###########################-->
          <surface>
            <friction>
              <ode>
                <mu>1</mu>
                <mu2>1</mu2>
              </ode>
            </friction>
          </surface>
<!--###########################-->
      </collision>
      <visual name='Empty_Link1_visual'>
        <pose frame=''>0 0 0 0 -0 0</pose>
        <geometry>
          <mesh>
            <scale>1 1 1</scale>
            <uri>model://gripper3/meshes/Empty_Link1.STL</uri>
          </mesh>
        </geometry>
      </visual>
    </link>
    <joint name='joint1' type='revolute'>
      <child>Empty_Link1</child>
      <parent>base_link</parent>
      <axis>
        <xyz>0 0 1</xyz>
        <limit>
          <lower>-0.5</lower>
          <upper>2</upper>
          <effort>0.5</effort>
          <velocity>0.1</velocity>
        </limit>
        <dynamics>
          <damping>0.0001</damping>
          <friction>0</friction>
          <spring_reference>0</spring_reference>
          <spring_stiffness>0</spring_stiffness>
        </dynamics>
        <use_parent_model_frame>0</use_parent_model_frame>
      </axis>
    </joint>
    <link name='Empty_Link2'>
      <pose frame=''>0.012 0 0.0195 -1.5708 0.96069 3.14159</pose>
      <inertial>
        <pose frame=''>-0.019265 -0.025888 -0.004777 0 -0 0</pose>
        <mass>0.1</mass>
        <inertia>
          <ixx>1.6519e-06</ixx>
          <ixy>-1.216e-06</ixy>
          <ixz>-7.2546e-17</ixz>
          <iyy>1.5595e-06</iyy>
          <iyz>-3.2073e-16</iyz>
          <izz>2.886e-06</izz>
        </inertia>
      </inertial>
      <collision name='Empty_Link2_collision'>
        <pose frame=''>0 0 0 0 -0 0</pose>
        <geometry>
          <mesh>
            <scale>1 1 1</scale>
            <uri>model://gripper3/meshes/Empty_Link2.STL</uri>
          </mesh>
        </geometry>
 <!--###########################-->
          <surface>
            <friction>
              <ode>
                <mu>1</mu>
                <mu2>1</mu2>
              </ode>
            </friction>
          </surface>
<!--###########################-->
      </collision>
      <visual name='Empty_Link2_visual'>
        <pose frame=''>0 0 0 0 -0 0</pose>
        <geometry>
          <mesh>
            <scale>1 1 1</scale>
            <uri>model://gripper3/meshes/Empty_Link2.STL</uri>
          </mesh>
        </geometry>
      </visual>
    </link>
    <joint name='joint2' type='revolute'>
      <child>Empty_Link2</child>
      <parent>base_link</parent>
      <axis>
        <xyz>0 0 -1</xyz>
        <limit>
          <lower>-0.5</lower>
          <upper>2</upper>
          <effort>0.5</effort>
          <velocity>0.1</velocity>
        </limit>
        <dynamics>
          <damping>0.0001</damping>
          <friction>0</friction>
          <spring_reference>0</spring_reference>
          <spring_stiffness>0</spring_stiffness>
        </dynamics>
        <use_parent_model_frame>0</use_parent_model_frame>
      </axis>
    </joint>
  <plugin name="gripper_control3_1" filename="libgripper_plugin3_1.so"/>
  <plugin name="gripper_control3_2" filename="libgripper_plugin3_2.so"/>
  </model>
</sdf>
