<?xml version="1.0" encoding="utf-8"?>
<!-- This URDF was automatically created by SolidWorks to URDF Exporter! Originally created by Stephen Brawner (brawner@gmail.com) 
     Commit Version: 1.6.0-4-g7f85cfe  Build Version: 1.6.7995.38578
     For more information, please see http://wiki.ros.org/sw_urdf_exporter -->
<robot
  name="gripper3">
  <link
    name="base_link">
    <inertial>
      <origin
        xyz="0.022563 0.018368 -0.0176"
        rpy="0 0 0" />
      <mass
        value="0.047774" />
      <inertia
        ixx="6.7162E-06"
        ixy="-1.004E-07"
        ixz="-7.4045E-08"
        iyy="1.0991E-05"
        iyz="-4.0881E-07"
        izz="7.9121E-06" />
    </inertial>
    <visual>
      <origin
        xyz="0 0 0"
        rpy="0 0 0" />
      <geometry>
        <mesh
          filename="package://gripper3/meshes/base_link.STL" />
      </geometry>
      <material
        name="">
        <color
          rgba="1 1 1 1" />
      </material>
    </visual>
    <collision>
      <origin
        xyz="0 0 0"
        rpy="0 0 0" />
      <geometry>
        <mesh
          filename="package://gripper3/meshes/base_link.STL" />
      </geometry>
    </collision>
  </link>
  <link
    name="Empty_Link1">
    <inertial>
      <origin
        xyz="-0.021122 0.028354 -0.0055832"
        rpy="0 0 0" />
      <mass
        value="0.015801" />
      <inertia
        ixx="1.6647E-06"
        ixy="1.223E-06"
        ixz="-1.3248E-16"
        iyy="1.5435E-06"
        iyz="-2.1754E-17"
        izz="2.8346E-06" />
    </inertial>
    <visual>
      <origin
        xyz="0 0 0"
        rpy="0 0 0" />
      <geometry>
        <mesh
          filename="package://gripper3/meshes/Empty_Link1.STL" />
      </geometry>
      <material
        name="">
        <color
          rgba="1 1 1 1" />
      </material>
    </visual>
    <collision>
      <origin
        xyz="0 0 0"
        rpy="0 0 0" />
      <geometry>
        <mesh
          filename="package://gripper3/meshes/Empty_Link1.STL" />
      </geometry>
    </collision>
  </link>
  <joint
    name="joint1"
    type="continuous">
    <origin
      xyz="0.04 0 0.02"
      rpy="1.5708 0.90665 0" />
    <parent
      link="base_link" />
    <child
      link="Empty_Link1" />
    <axis
      xyz="0 0 1" />
  </joint>
  <link
    name="Empty_Link2">
    <inertial>
      <origin
        xyz="-0.019265 -0.025888 -0.004777"
        rpy="0 0 0" />
      <mass
        value="0.017262" />
      <inertia
        ixx="1.6519E-06"
        ixy="-1.216E-06"
        ixz="-7.2546E-17"
        iyy="1.5595E-06"
        iyz="-3.2073E-16"
        izz="2.886E-06" />
    </inertial>
    <visual>
      <origin
        xyz="0 0 0"
        rpy="0 0 0" />
      <geometry>
        <mesh
          filename="package://gripper3/meshes/Empty_Link2.STL" />
      </geometry>
      <material
        name="">
        <color
          rgba="1 1 1 1" />
      </material>
    </visual>
    <collision>
      <origin
        xyz="0 0 0"
        rpy="0 0 0" />
      <geometry>
        <mesh
          filename="package://gripper3/meshes/Empty_Link2.STL" />
      </geometry>
    </collision>
  </link>
  <joint
    name="joint2"
    type="continuous">
    <origin
      xyz="0.012 0 0.0195"
      rpy="-1.5708 0.96069 -3.1416" />
    <parent
      link="base_link" />
    <child
      link="Empty_Link2" />
    <axis
      xyz="0 0 -1" />
  </joint>
</robot>