<sdf version='1.5'>
  <model name='FlyingDeltaEntire'>
    <include>
      <uri>model://FlyingDelta</uri>
      <pose>0 0 1.60 0 0 0</pose>
    </include>
    <include>
      <uri>model://FlyingDeltaArmBase</uri>
      <pose>0 0 1.503 0 0 0</pose>
    </include>
    <include>
      <uri>model://velodyne_VLP_16</uri>
      <pose>0 0 1.66 0 0 0</pose>
    </include>
    <joint name="velodyne_base_mount_joint" type="fixed">
      <parent>FlyingDelta::base_link</parent>
      <child>velodyne_VLP_16::velodyne_base_link</child>
    </joint>
    <joint name="velodyne_base_mount_joint_2" type="fixed">
      <parent>FlyingDelta::base_link</parent>
      <child>velodyne_VLP_16::velodyne</child>
    </joint>
    <include>
      <uri>model://FlyingDeltaArmLow</uri>
      <pose>0 0 1.7265 0 0 0.5236</pose>
    </include>
    <include>
      <uri>model://depth_camera</uri>
      <pose>0.1 0 1.6 0 0 0</pose>
    </include>
    <joint name="depth_camera_joint" type="revolute">
      <child>depth_camera::link</child>
      <parent>FlyingDelta::base_link</parent>
      <axis>
        <xyz>0 0 1</xyz>
        <limit>
          <upper>0</upper>
          <lower>0</lower>
        </limit>
      </axis>
    </joint>
<!--    <joint name='base' type='fixed'>-->
<!--      <child>FlyingDelta::base_link</child>-->
<!--      <parent>world</parent>-->
<!--    </joint>-->
    <joint name="Mbase" type="fixed">
      <child>FlyingDelta::base_link</child>
      <parent>FlyingDeltaArmBase::link_0</parent>
    </joint>
    <joint name='uleg1_con' type='revolute'>
      <child>FlyingDeltaArmLow::con1</child>
      <parent>FlyingDeltaArmBase::uleg_3</parent>
      <axis>
        <xyz>-0.5 0.8660254 0</xyz>
        <limit>
          <lower>-1e+16</lower>
          <upper>1e+16</upper>
        </limit>
        <dynamics>
          <spring_reference>0</spring_reference>
          <spring_stiffness>0</spring_stiffness>
          <damping>0.00</damping>
	  <friction>0.00</friction>
        </dynamics>
        <use_parent_model_frame>1</use_parent_model_frame>
      </axis>
    </joint>
   <joint name='uleg2_con' type='revolute'>
      <child>FlyingDeltaArmLow::con2</child>
      <parent>FlyingDeltaArmBase::uleg_1</parent>
      <axis>
        <xyz>1 0 0</xyz>
        <limit>
          <lower>-1e+16</lower>
          <upper>1e+16</upper>
        </limit>
        <dynamics>
          <spring_reference>0</spring_reference>
          <spring_stiffness>0</spring_stiffness>
          <damping>0.00</damping>
	  <friction>0.00</friction>
        </dynamics>
        <use_parent_model_frame>1</use_parent_model_frame>
      </axis>
    </joint>
   <joint name='uleg3_con' type='revolute'>
      <child>FlyingDeltaArmLow::con3</child>
      <parent>FlyingDeltaArmBase::uleg_2</parent>
      <axis>
        <xyz>0.5 0.8660254 0</xyz>
        <limit>
          <lower>-1e+16</lower>
          <upper>1e+16</upper>
        </limit>
        <dynamics>
          <spring_reference>0</spring_reference>
          <spring_stiffness>0</spring_stiffness>
          <damping>0.00</damping>
	  <friction>0.00</friction>
        </dynamics>
        <use_parent_model_frame>1</use_parent_model_frame>
      </axis>
    </joint>
   <plugin name="p3d_base_controller" filename="libgazebo_ros_p3d.so">
    <alwaysOn>true</alwaysOn>
    <updateRate>100.0</updateRate>
    <bodyName>FlyingDeltaArmLow::low_base</bodyName>
    <topicName>ground_truth/relative_pos</topicName>
    <gaussianNoise>0.00</gaussianNoise>
    <frameName>FlyingDelta::base_link</frameName>
    <xyzOffsets>0 0 0</xyzOffsets>
    <rpyOffsets>0 0 0</rpyOffsets>
  </plugin>
  <plugin name="p3d_base_controller" filename="libgazebo_ros_p3d.so">
    <alwaysOn>true</alwaysOn>
    <updateRate>100.0</updateRate>
    <bodyName>FlyingDeltaArmLow::low_base</bodyName>
    <topicName>ground_truth/position_end_effc</topicName>
    <gaussianNoise>0.00</gaussianNoise>
    <frameName>world</frameName>
    <xyzOffsets>0 0 0</xyzOffsets>
    <rpyOffsets>0 0 0</rpyOffsets>
  </plugin>
   <plugin name="p3d_base_controller" filename="libgazebo_ros_p3d.so">
    <alwaysOn>true</alwaysOn>
    <updateRate>100.0</updateRate>
    <bodyName>FlyingDelta::base_link</bodyName>
    <topicName>ground_truth/positon_uav_up</topicName>
    <gaussianNoise>0</gaussianNoise>
    <frameName>world</frameName>
    <xyzOffsets>0 0 0</xyzOffsets>
    <rpyOffsets>0 0 0</rpyOffsets>
  </plugin>
    <static>0</static>
    <self_collide>0</self_collide>
    <enable_wind>0</enable_wind>
  </model>
</sdf>
