<sdf version='1.5'>
  <model name='FlyingDeltaArmBase'>
    <link name='link_0'>
      <pose frame=''>0 0 0 0 -0 0</pose>
      <inertial>
        <pose frame=''>-0 -0 -0 0 -0 0</pose>
        <mass>0.5</mass>
        <inertia>
          <ixx>0.0004708</ixx>
          <ixy>0</ixy>
          <ixz>0</ixz>
          <iyy>0.0004708</iyy>
          <iyz>0</iyz>
          <izz>0.0004083</izz>
        </inertia>
      </inertial>
      <collision name='link_0_collision'>
       <pose frame=''>0 0 0 0 -0 0</pose>
        <geometry>
          <box>
            <size>0.07 0.07 0.08</size>
          </box>
        </geometry>
      </collision>
      <visual name='link_0_visual'>
        <pose frame=''>-0.1065 -0.117 -0.065 0 0 0</pose>
        <geometry>
          <mesh>
            <scale>0.001 0.001 0.001</scale>
            <uri>model://FlyingDelta/meshes/base_low.STL</uri>
          </mesh>
        </geometry>
        <material>
          <script>
            <uri>file://media/materials/scripts/gazebo.material</uri>
            <name>Gazebo/Red</name>
          </script>
        </material>
      </visual>
      <gravity>0</gravity>
      <velocity_decay/>
    </link>



    <link name='uleg_1'>
      <pose frame=''>0 -0.1 -0.0155 1.1 0 0</pose>
      <inertial>
        <pose frame=''>0 0 0 0 0 0</pose>
        <mass>0.04</mass>
        <inertia>
          <ixx>0.00020032</ixx>
          <ixy>0</ixy>
          <ixz>0</ixz>
          <iyy>0.0000166664</iyy>
          <iyz>0</iyz>
          <izz>0.00020032</izz>
        </inertia>
      </inertial>
      <collision name='uleg_1_collision'>
        <pose frame=''>-0.0087 0.03 -0.05 0 0 -2.0944</pose>
        <geometry>
          <mesh>
            <scale>0.001 0.001 0.001</scale>
            <uri>model://FlyingDelta/meshes/arm.STL</uri>
          </mesh>
        </geometry>
      </collision>
      <visual name='uleg_1_visual'>
        <pose frame=''>-0.0087 0.03 -0.05 0 0 -2.0944</pose>
        <geometry>
          <mesh>
            <scale>0.001 0.001 0.001</scale>
            <uri>model://FlyingDelta/meshes/arm.STL</uri>
          </mesh>
        </geometry>
        <material>
          <script>
            <uri>file://media/materials/scripts/gazebo.material</uri>
            <name>Gazebo/DarkYellow</name>
          </script>
        </material>
      </visual>
      <gravity>1</gravity>
      <velocity_decay/>
    </link>
        <link name='uleg_2'>
      <pose frame=''> -0.0866 0.05 -0.0155 1.1 0 -2.0944</pose>
      <inertial>
        <pose frame=''>0 0 0 0 0 0</pose>
        <mass>0.04</mass>
        <inertia>
          <ixx>0.00020032</ixx>
          <ixy>0</ixy>
          <ixz>0</ixz>
          <iyy>0.0000166664</iyy>
          <iyz>0</iyz>
          <izz>0.00020032</izz>
        </inertia>
      </inertial>
      <collision name='uleg_2_collision'>
        <pose frame=''>-0.0087 0.03 -0.05 0 0 -2.0944</pose>
        <geometry>
          <mesh>
            <scale>0.001 0.001 0.001</scale>
            <uri>model://FlyingDelta/meshes/arm.STL</uri>
          </mesh>
        </geometry>
      </collision>
      <visual name='uleg_2_visual'>
        <pose frame=''>-0.0087 0.03 -0.05 0 0 -2.0944</pose>
        <geometry>
          <mesh>
            <scale>0.001 0.001 0.001</scale>
            <uri>model://FlyingDelta/meshes/arm.STL</uri>
          </mesh>
        </geometry>
        <material>
          <script>
            <uri>file://media/materials/scripts/gazebo.material</uri>
            <name>Gazebo/DarkYellow</name>
          </script>
        </material>
      </visual>
      <gravity>1</gravity>
      <velocity_decay/>
    </link>
    <link name='uleg_3'>
      <pose frame=''>0.0866 0.05  -0.0155 1.1 0 2.0944</pose>
      <inertial>
        <pose frame=''>0 0 0 0 0 0</pose>
        <mass>0.04</mass>
        <inertia>
          <ixx>0.00020032</ixx>
          <ixy>0</ixy>
          <ixz>0</ixz>
          <iyy>0.0000166664</iyy>
          <iyz>0</iyz>
          <izz>0.00020032</izz>
        </inertia>
      </inertial>
      <collision name='uleg_3_collision'>
        <pose frame=''>-0.0087 0.03 -0.05 0 0 -2.0944</pose>
        <geometry>
          <mesh>
            <scale>0.001 0.001 0.001</scale>
            <uri>model://FlyingDelta/meshes/arm.STL</uri>
          </mesh>
        </geometry>
      </collision>
      <visual name='uleg_3_visual'>
        <pose frame=''>-0.0087 0.03 -0.05 0 0 -2.0944</pose>
        <geometry>
          <mesh>
            <scale>0.001 0.001 0.001</scale>
            <uri>model://FlyingDelta/meshes/arm.STL</uri>
          </mesh>
        </geometry>
        <material>
          <script>
            <uri>file://media/materials/scripts/gazebo.material</uri>
            <name>Gazebo/DarkYellow</name>
          </script>
        </material>
      </visual>
      <gravity>1</gravity>
      <velocity_decay/>
    </link>
    <joint name='link_0_JOINT_1' type='revolute'>
      <child>uleg_1</child>
      <parent>link_0</parent>
      <axis>
        <xyz>1 0 0</xyz>
        <limit>
          <lower>-10</lower>
          <upper>10</upper>
          <effort>2</effort>
          <velocity>1</velocity>
        </limit>
        <dynamics>
          <spring_reference>0</spring_reference>
          <spring_stiffness>0</spring_stiffness>
          <damping>0</damping>
          <friction>0</friction>
        </dynamics>
        <use_parent_model_frame>1</use_parent_model_frame>
      </axis>
    </joint>
    <joint name='link_0_JOINT_2' type='revolute'>
      <child>uleg_2</child>
      <parent>link_0</parent>
      <axis>
        <xyz>-0.5 -0.86602540378 0</xyz>
        <limit>
          <lower>-10</lower>
          <upper>10</upper>
          <effort>2</effort>
          <velocity>1</velocity>
        </limit>
        <dynamics>
          <spring_reference>0</spring_reference>
          <spring_stiffness>0</spring_stiffness>
          <damping>0</damping>
          <friction>0</friction>
        </dynamics>
        <use_parent_model_frame>1</use_parent_model_frame>
      </axis>
    </joint>

    <joint name='link_0_JOINT_3' type='revolute'>
      <child>uleg_3</child>
      <parent>link_0</parent>
      <axis>
        <xyz>-0.5 0.86602540378 0</xyz>
        <limit>
          <lower>-10</lower>
          <upper>10</upper>
          <effort>2</effort>
          <velocity>1</velocity>
        </limit>
        <dynamics>
          <spring_reference>0</spring_reference>
          <spring_stiffness>0</spring_stiffness>
          <damping>0</damping>
          <friction>0</friction>
        </dynamics>
        <use_parent_model_frame>1</use_parent_model_frame>
      </axis>
    </joint>

    <static>0</static>
    <self_collide>0</self_collide>
    <enable_wind>0</enable_wind>


       <plugin name="delta_control1" filename="libdelta_plugin1.so"/>
       <plugin name="delta_control2" filename="libdelta_plugin2.so"/>
       <plugin name="delta_control3" filename="libdelta_plugin3.so"/>

  </model>
</sdf>
