<sdf version='1.6'>
  <model name='landing_leg'>
    <link name='base_link'>
      <pose frame=''>0 0 0 0 -0 0</pose>
      <inertial>
        <pose frame=''>-0 -0 -0.077877 0 -0 0</pose>
        <mass>0.12479</mass>
        <inertia>
          <ixx>0.0027513</ixx>
          <ixy>9.4494e-16</ixy>
          <ixz>-8.7806e-15</ixz>
          <iyy>0.0027513</iyy>
          <iyz>-1.0013e-14</iyz>
          <izz>0.0049694</izz>
        </inertia>
      </inertial>
      <collision name='base_link_collision'>
        <pose frame=''>0 0 0 0 -0 0</pose>
        <geometry>
          <mesh>
            <scale>1 1 1</scale>
            <uri>model://landing_leg/meshes/base_link.STL</uri>
          </mesh>
        </geometry>
      </collision>
      <visual name='base_link_visual'>
        <pose frame=''>0 0 0 0 -0 0</pose>
        <geometry>
          <mesh>
            <scale>1 1 1</scale>
            <uri>model://landing_leg/meshes/base_link.STL</uri>
          </mesh>
        </geometry>
      </visual>
    </link>
    <link name='link1'>
      <pose frame=''>0.0245 -0.129 -0.093 0 -0 0</pose>
      <inertial>
        <pose frame=''>-0.02425 -0.030225 -0.046837 0 -0 0</pose>
        <mass>0.037564</mass>
        <inertia>
          <ixx>7.4131e-05</ixx>
          <ixy>0</ixy>
          <ixz>0</ixz>
          <iyy>5.2962e-05</iyy>
          <iyz>-3.1562e-05</iyz>
          <izz>2.442e-05</izz>
        </inertia>
      </inertial>
      <collision name='link1_collision'>
        <pose frame=''>0 0 0 0 -0 0</pose>
        <geometry>
          <mesh>
            <scale>1 1 1</scale>
            <uri>model://landing_leg/meshes/link1.STL</uri>
          </mesh>
        </geometry>
      </collision>
      <visual name='link1_visual'>
        <pose frame=''>0 0 0 0 -0 0</pose>
        <geometry>
          <mesh>
            <scale>1 1 1</scale>
            <uri>model://landing_leg/meshes/link1.STL</uri>
          </mesh>
        </geometry>
      </visual>
    </link>
    <joint name='joint1' type='revolute'>
      <child>link1</child>
      <parent>base_link</parent>
      <axis>
        <xyz>1 0 0</xyz>
        <limit>
          <lower>-3</lower>
          <upper>3</upper>
          <effort>10</effort>
          <velocity>10</velocity>
        </limit>
        <dynamics>
          <spring_reference>0</spring_reference>
          <spring_stiffness>0</spring_stiffness>
        </dynamics>
        <use_parent_model_frame>0</use_parent_model_frame>
      </axis>
    </joint>
    <link name='link1_1'>
      <pose frame=''>0.0095 -0.25317 -0.28541 0 -0 0</pose>
      <inertial>
        <pose frame=''>-0.009062 0 0 0 -0 0</pose>
        <mass>0.01515</mass>
        <inertia>
          <ixx>1.5658e-06</ixx>
          <ixy>0</ixy>
          <ixz>0</ixz>
          <iyy>6.1989e-07</iyy>
          <iyz>-1.6374e-07</iyz>
          <izz>1.6121e-06</izz>
        </inertia>
      </inertial>
      <collision name='link1_1_collision'>
        <pose frame=''>0 0 0 0 -0 0</pose>
        <geometry>
          <mesh>
            <scale>1 1 1</scale>
            <uri>model://landing_leg/meshes/link1_1.STL</uri>
          </mesh>
        </geometry>
      </collision>
      <visual name='link1_1_visual'>
        <pose frame=''>0 0 0 0 -0 0</pose>
        <geometry>
          <mesh>
            <scale>1 1 1</scale>
            <uri>model://landing_leg/meshes/link1_1.STL</uri>
          </mesh>
        </geometry>
      </visual>
    </link>
    <joint name='joint1_1' type='revolute'>
      <child>link1_1</child>
      <parent>link1</parent>
      <axis>
        <xyz>1 0 0</xyz>
        <limit>
          <lower>-3</lower>
          <upper>3</upper>
          <effort>10</effort>
          <velocity>10</velocity>
        </limit>
        <dynamics>
          <spring_reference>0</spring_reference>
          <spring_stiffness>0</spring_stiffness>
        </dynamics>
        <use_parent_model_frame>0</use_parent_model_frame>
      </axis>
    </joint>
    <link name='link2'>
      <pose frame=''>0.129 0.0245 -0.093 0 -0 0</pose>
      <inertial>
        <pose frame=''>0.030225 -0.02425 -0.046837 0 -0 0</pose>
        <mass>0.037564</mass>
        <inertia>
          <ixx>5.2962e-05</ixx>
          <ixy>0</ixy>
          <ixz>3.1562e-05</ixz>
          <iyy>7.4131e-05</iyy>
          <iyz>0</iyz>
          <izz>2.442e-05</izz>
        </inertia>
      </inertial>
      <collision name='link2_collision'>
        <pose frame=''>0 0 0 0 -0 0</pose>
        <geometry>
          <mesh>
            <scale>1 1 1</scale>
            <uri>model://landing_leg/meshes/link2.STL</uri>
          </mesh>
        </geometry>
      </collision>
      <visual name='link2_visual'>
        <pose frame=''>0 0 0 0 -0 0</pose>
        <geometry>
          <mesh>
            <scale>1 1 1</scale>
            <uri>model://landing_leg/meshes/link2.STL</uri>
          </mesh>
        </geometry>
      </visual>
    </link>
    <joint name='joint2' type='revolute'>
      <child>link2</child>
      <parent>base_link</parent>
      <axis>
        <xyz>0 1 0</xyz>
        <limit>
          <lower>-3</lower>
          <upper>3</upper>
          <effort>10</effort>
          <velocity>10</velocity>
        </limit>
        <dynamics>
          <spring_reference>0</spring_reference>
          <spring_stiffness>0</spring_stiffness>
        </dynamics>
        <use_parent_model_frame>0</use_parent_model_frame>
      </axis>
    </joint>
    <link name='link2_1'>
      <pose frame=''>0.25317 0.0095 -0.28541 0 -0 0</pose>
      <inertial>
        <pose frame=''>0 -0.009062 0 0 -0 0</pose>
        <mass>0.01515</mass>
        <inertia>
          <ixx>6.1989e-07</ixx>
          <ixy>0</ixy>
          <ixz>1.6374e-07</ixz>
          <iyy>1.5658e-06</iyy>
          <iyz>0</iyz>
          <izz>1.6121e-06</izz>
        </inertia>
      </inertial>
      <collision name='link2_1_collision'>
        <pose frame=''>0 0 0 0 -0 0</pose>
        <geometry>
          <mesh>
            <scale>1 1 1</scale>
            <uri>model://landing_leg/meshes/link2_1.STL</uri>
          </mesh>
        </geometry>
      </collision>
      <visual name='link2_1_visual'>
        <pose frame=''>0 0 0 0 -0 0</pose>
        <geometry>
          <mesh>
            <scale>1 1 1</scale>
            <uri>model://landing_leg/meshes/link2_1.STL</uri>
          </mesh>
        </geometry>
      </visual>
    </link>
    <joint name='joint2_1' type='revolute'>
      <child>link2_1</child>
      <parent>link2</parent>
      <axis>
        <xyz>0 1 0</xyz>
        <limit>
          <lower>-3</lower>
          <upper>3</upper>
          <effort>10</effort>
          <velocity>10</velocity>
        </limit>
        <dynamics>
          <spring_reference>0</spring_reference>
          <spring_stiffness>0</spring_stiffness>
        </dynamics>
        <use_parent_model_frame>0</use_parent_model_frame>
      </axis>
    </joint>
    <link name='link3'>
      <pose frame=''>-0.0245 0.129 -0.093 0 -0 0</pose>
      <inertial>
        <pose frame=''>0.02425 0.030225 -0.046837 0 -0 0</pose>
        <mass>0.037564</mass>
        <inertia>
          <ixx>7.4131e-05</ixx>
          <ixy>0</ixy>
          <ixz>0</ixz>
          <iyy>5.2962e-05</iyy>
          <iyz>3.1562e-05</iyz>
          <izz>2.442e-05</izz>
        </inertia>
      </inertial>
      <collision name='link3_collision'>
        <pose frame=''>0 0 0 0 -0 0</pose>
        <geometry>
          <mesh>
            <scale>1 1 1</scale>
            <uri>model://landing_leg/meshes/link3.STL</uri>
          </mesh>
        </geometry>
      </collision>
      <visual name='link3_visual'>
        <pose frame=''>0 0 0 0 -0 0</pose>
        <geometry>
          <mesh>
            <scale>1 1 1</scale>
            <uri>model://landing_leg/meshes/link3.STL</uri>
          </mesh>
        </geometry>
      </visual>
    </link>
    <joint name='joint3' type='revolute'>
      <child>link3</child>
      <parent>base_link</parent>
      <axis>
        <xyz>-1 0 0</xyz>
        <limit>
          <lower>-3</lower>
          <upper>3</upper>
          <effort>10</effort>
          <velocity>10</velocity>
        </limit>
        <dynamics>
          <spring_reference>0</spring_reference>
          <spring_stiffness>0</spring_stiffness>
        </dynamics>
        <use_parent_model_frame>0</use_parent_model_frame>
      </axis>
    </joint>
    <link name='link3_1'>
      <pose frame=''>-0.0095 0.25317 -0.28541 0 -0 0</pose>
      <inertial>
        <pose frame=''>0.009062 -0 0 0 -0 0</pose>
        <mass>0.01515</mass>
        <inertia>
          <ixx>1.5658e-06</ixx>
          <ixy>0</ixy>
          <ixz>0</ixz>
          <iyy>6.1989e-07</iyy>
          <iyz>1.6374e-07</iyz>
          <izz>1.6121e-06</izz>
        </inertia>
      </inertial>
      <collision name='link3_1_collision'>
        <pose frame=''>0 0 0 0 -0 0</pose>
        <geometry>
          <mesh>
            <scale>1 1 1</scale>
            <uri>model://landing_leg/meshes/link3_1.STL</uri>
          </mesh>
        </geometry>
      </collision>
      <visual name='link3_1_visual'>
        <pose frame=''>0 0 0 0 -0 0</pose>
        <geometry>
          <mesh>
            <scale>1 1 1</scale>
            <uri>model://landing_leg/meshes/link3_1.STL</uri>
          </mesh>
        </geometry>
      </visual>
    </link>
    <joint name='joint3_1' type='revolute'>
      <child>link3_1</child>
      <parent>link3</parent>
      <axis>
        <xyz>-1 0 0</xyz>
        <limit>
          <lower>-3</lower>
          <upper>3</upper>
          <effort>10</effort>
          <velocity>10</velocity>
        </limit>
        <dynamics>
          <spring_reference>0</spring_reference>
          <spring_stiffness>0</spring_stiffness>
        </dynamics>
        <use_parent_model_frame>0</use_parent_model_frame>
      </axis>
    </joint>
    <link name='link4'>
      <pose frame=''>-0.129 -0.0245 -0.093 0 -0 0</pose>
      <inertial>
        <pose frame=''>-0.030225 0.02425 -0.046837 0 -0 0</pose>
        <mass>0.037564</mass>
        <inertia>
          <ixx>5.2962e-05</ixx>
          <ixy>0</ixy>
          <ixz>-3.1562e-05</ixz>
          <iyy>7.4131e-05</iyy>
          <iyz>0</iyz>
          <izz>2.442e-05</izz>
        </inertia>
      </inertial>
      <collision name='link4_collision'>
        <pose frame=''>0 0 0 0 -0 0</pose>
        <geometry>
          <mesh>
            <scale>1 1 1</scale>
            <uri>model://landing_leg/meshes/link4.STL</uri>
          </mesh>
        </geometry>
      </collision>
      <visual name='link4_visual'>
        <pose frame=''>0 0 0 0 -0 0</pose>
        <geometry>
          <mesh>
            <scale>1 1 1</scale>
            <uri>model://landing_leg/meshes/link4.STL</uri>
          </mesh>
        </geometry>
      </visual>
    </link>
    <joint name='joint4' type='revolute'>
      <child>link4</child>
      <parent>base_link</parent>
      <axis>
        <xyz>0 -1 0</xyz>
        <limit>
          <lower>-3</lower>
          <upper>3</upper>
          <effort>10</effort>
          <velocity>10</velocity>
        </limit>
        <dynamics>
          <spring_reference>0</spring_reference>
          <spring_stiffness>0</spring_stiffness>
        </dynamics>
        <use_parent_model_frame>0</use_parent_model_frame>
      </axis>
    </joint>
    <link name='link4_1'>
      <pose frame=''>-0.25317 -0.0085 -0.28541 0 -0 0</pose>
      <inertial>
        <pose frame=''>0 0.008062 0 0 -0 0</pose>
        <mass>0.01515</mass>
        <inertia>
          <ixx>6.1989e-07</ixx>
          <ixy>0</ixy>
          <ixz>-1.6374e-07</ixz>
          <iyy>1.5658e-06</iyy>
          <iyz>0</iyz>
          <izz>1.6121e-06</izz>
        </inertia>
      </inertial>
      <collision name='link4_1_collision'>
        <pose frame=''>0 0 0 0 -0 0</pose>
        <geometry>
          <mesh>
            <scale>1 1 1</scale>
            <uri>model://landing_leg/meshes/link4_1.STL</uri>
          </mesh>
        </geometry>
      </collision>
      <visual name='link4_1_visual'>
        <pose frame=''>0 0 0 0 -0 0</pose>
        <geometry>
          <mesh>
            <scale>1 1 1</scale>
            <uri>model://landing_leg/meshes/link4_1.STL</uri>
          </mesh>
        </geometry>
      </visual>
    </link>
    <joint name='joint4_1' type='revolute'>
      <child>link4_1</child>
      <parent>link4</parent>
      <axis>
        <xyz>0 -1 0</xyz>
        <limit>
          <lower>-3</lower>
          <upper>3</upper>
          <effort>10</effort>
          <velocity>10</velocity>
        </limit>
        <dynamics>
          <spring_reference>0</spring_reference>
          <spring_stiffness>0</spring_stiffness>
        </dynamics>
        <use_parent_model_frame>0</use_parent_model_frame>
      </axis>
    </joint>
  </model>
</sdf>
