<?xml version="1.0" encoding="utf-8"?>
<!-- This URDF was automatically created by SolidWorks to URDF Exporter! Originally created by Stephen Brawner (brawner@gmail.com) 
     Commit Version: 1.6.0-4-g7f85cfe  Build Version: 1.6.7995.38578
     For more information, please see http://wiki.ros.org/sw_urdf_exporter -->
<robot
  name="landing_leg">
  <link
    name="base_link">
    <inertial>
      <origin
        xyz="-1.7847E-11 -8.2696E-11 -0.077877"
        rpy="0 0 0" />
      <mass
        value="0.12479" />
      <inertia
        ixx="0.0027513"
        ixy="9.4479E-16"
        ixz="-8.7805E-15"
        iyy="0.0027513"
        iyz="-1.0013E-14"
        izz="0.0049695" />
    </inertial>
    <visual>
      <origin
        xyz="0 0 0"
        rpy="0 0 0" />
      <geometry>
        <mesh
          filename="package://landing_leg/meshes/base_link.STL" />
      </geometry>
      <material
        name="">
        <color
          rgba="0.79216 0.81961 0.93333 1" />
      </material>
    </visual>
    <collision>
      <origin
        xyz="0 0 0"
        rpy="0 0 0" />
      <geometry>
        <mesh
          filename="package://landing_leg/meshes/base_link.STL" />
      </geometry>
    </collision>
  </link>
  <link
    name="link1">
    <inertial>
      <origin
        xyz="-0.02425 -0.055743 1.8079E-08"
        rpy="0 0 0" />
      <mass
        value="0.037564" />
      <inertia
        ixx="7.4131E-05"
        ixy="4.7361E-19"
        ixz="8.8923E-22"
        iyy="4.052E-06"
        iyz="-8.3037E-12"
        izz="7.333E-05" />
    </inertial>
    <visual>
      <origin
        xyz="0 0 0"
        rpy="0 0 0" />
      <geometry>
        <mesh
          filename="package://landing_leg/meshes/link1.STL" />
      </geometry>
      <material
        name="">
        <color
          rgba="0.79216 0.81961 0.93333 1" />
      </material>
    </visual>
    <collision>
      <origin
        xyz="0 0 0"
        rpy="0 0 0" />
      <geometry>
        <mesh
          filename="package://landing_leg/meshes/link1.STL" />
      </geometry>
    </collision>
  </link>
  <joint
    name="joint1"
    type="revolute">
    <origin
      xyz="0.0245 -0.129 -0.093"
      rpy="0 0 0" />
    <parent
      link="base_link" />
    <child
      link="link1" />
    <axis
      xyz="1 0 0" />
    <limit
      lower="-3"
      upper="3"
      effort="10"
      velocity="10" />
  </joint>
  <link
    name="link1_1">
    <inertial>
      <origin
        xyz="-0.0090618 -4.996E-16 -2.7756E-16"
        rpy="0 0 0" />
      <mass
        value="0.01515" />
      <inertia
        ixx="1.5658E-06"
        ixy="6.7142E-21"
        ixz="3.8689E-22"
        iyy="5.9484E-07"
        iyz="-3.6442E-08"
        izz="1.6371E-06" />
    </inertial>
    <visual>
      <origin
        xyz="0 0 0"
        rpy="0 0 0" />
      <geometry>
        <mesh
          filename="package://landing_leg/meshes/link1_1.STL" />
      </geometry>
      <material
        name="">
        <color
          rgba="0.79216 0.81961 0.93333 1" />
      </material>
    </visual>
    <collision>
      <origin
        xyz="0 0 0"
        rpy="0 0 0" />
      <geometry>
        <mesh
          filename="package://landing_leg/meshes/link1_1.STL" />
      </geometry>
    </collision>
  </link>
  <joint
    name="joint1_1"
    type="revolute">
    <origin
      xyz="-0.015 -0.229 0"
      rpy="0 0 0" />
    <parent
      link="link1" />
    <child
      link="link1_1" />
    <axis
      xyz="1 0 0" />
    <limit
      lower="-5"
      upper="5"
      effort="10"
      velocity="10" />
  </joint>
  <link
    name="link2">
    <inertial>
      <origin
        xyz="0.055743 -0.02425 1.8079E-08"
        rpy="0 0 0" />
      <mass
        value="0.037564" />
      <inertia
        ixx="4.052E-06"
        ixy="-7.1855E-19"
        ixz="8.3037E-12"
        iyy="7.4131E-05"
        iyz="5.239E-22"
        izz="7.333E-05" />
    </inertial>
    <visual>
      <origin
        xyz="0 0 0"
        rpy="0 0 0" />
      <geometry>
        <mesh
          filename="package://landing_leg/meshes/link2.STL" />
      </geometry>
      <material
        name="">
        <color
          rgba="0.79216 0.81961 0.93333 1" />
      </material>
    </visual>
    <collision>
      <origin
        xyz="0 0 0"
        rpy="0 0 0" />
      <geometry>
        <mesh
          filename="package://landing_leg/meshes/link2.STL" />
      </geometry>
    </collision>
  </link>
  <joint
    name="joint2"
    type="revolute">
    <origin
      xyz="0.129 0.0245 -0.093"
      rpy="0 0 0" />
    <parent
      link="base_link" />
    <child
      link="link2" />
    <axis
      xyz="0 1 0" />
    <limit
      lower="-3"
      upper="3"
      effort="10"
      velocity="10" />
  </joint>
  <link
    name="link2_1">
    <inertial>
      <origin
        xyz="6.66133814775094E-16 -0.00906181639868866 -2.22044604925031E-16"
        rpy="0 0 0" />
      <mass
        value="0.0151495097581002" />
      <inertia
        ixx="5.9483985467588E-07"
        ixy="-1.02486619041371E-20"
        ixz="3.64420390973363E-08"
        iyy="1.56580477541631E-06"
        iyz="5.10203576022058E-22"
        izz="1.63713073236488E-06" />
    </inertial>
    <visual>
      <origin
        xyz="0 0 0"
        rpy="0 0 0" />
      <geometry>
        <mesh
          filename="package://landing_leg/meshes/link2_1.STL" />
      </geometry>
      <material
        name="">
        <color
          rgba="0.792156862745098 0.819607843137255 0.933333333333333 1" />
      </material>
    </visual>
    <collision>
      <origin
        xyz="0 0 0"
        rpy="0 0 0" />
      <geometry>
        <mesh
          filename="package://landing_leg/meshes/link2_1.STL" />
      </geometry>
    </collision>
  </link>
  <joint
    name="joint2_1"
    type="revolute">
    <origin
      xyz="0.229 -0.015 0"
      rpy="0 0 0" />
    <parent
      link="link2" />
    <child
      link="link2_1" />
    <axis
      xyz="0 1 0" />
    <limit
      lower="-5"
      upper="5"
      effort="10"
      velocity="10" />
  </joint>
  <link
    name="link3">
    <inertial>
      <origin
        xyz="0.02425 0.055743 1.8079E-08"
        rpy="0 0 0" />
      <mass
        value="0.037564" />
      <inertia
        ixx="7.4131E-05"
        ixy="-1.5448E-20"
        ixz="-4.348E-22"
        iyy="4.052E-06"
        iyz="8.3037E-12"
        izz="7.333E-05" />
    </inertial>
    <visual>
      <origin
        xyz="0 0 0"
        rpy="0 0 0" />
      <geometry>
        <mesh
          filename="package://landing_leg/meshes/link3.STL" />
      </geometry>
      <material
        name="">
        <color
          rgba="0.79216 0.81961 0.93333 1" />
      </material>
    </visual>
    <collision>
      <origin
        xyz="0 0 0"
        rpy="0 0 0" />
      <geometry>
        <mesh
          filename="package://landing_leg/meshes/link3.STL" />
      </geometry>
    </collision>
  </link>
  <joint
    name="joint3"
    type="revolute">
    <origin
      xyz="-0.0245 0.129 -0.093"
      rpy="0 0 0" />
    <parent
      link="base_link" />
    <child
      link="link3" />
    <axis
      xyz="-1 0 0" />
    <limit
      lower="-3"
      upper="3"
      effort="10"
      velocity="10" />
  </joint>
  <link
    name="link3_1">
    <inertial>
      <origin
        xyz="0.0090618 4.4409E-16 -2.7756E-16"
        rpy="0 0 0" />
      <mass
        value="0.01515" />
      <inertia
        ixx="1.5658E-06"
        ixy="-2.4E-22"
        ixz="-1.1005E-22"
        iyy="5.9484E-07"
        iyz="3.6442E-08"
        izz="1.6371E-06" />
    </inertial>
    <visual>
      <origin
        xyz="0 0 0"
        rpy="0 0 0" />
      <geometry>
        <mesh
          filename="package://landing_leg/meshes/link3_1.STL" />
      </geometry>
      <material
        name="">
        <color
          rgba="0.79216 0.81961 0.93333 1" />
      </material>
    </visual>
    <collision>
      <origin
        xyz="0 0 0"
        rpy="0 0 0" />
      <geometry>
        <mesh
          filename="package://landing_leg/meshes/link3_1.STL" />
      </geometry>
    </collision>
  </link>
  <joint
    name="joint3_1"
    type="revolute">
    <origin
      xyz="0.015 0.229 0"
      rpy="0 0 0" />
    <parent
      link="link3" />
    <child
      link="link3_1" />
    <axis
      xyz="-1 0 0" />
    <limit
      lower="-5"
      upper="5"
      effort="10"
      velocity="10" />
  </joint>
  <link
    name="link4">
    <inertial>
      <origin
        xyz="-0.055743 0.02425 1.8079E-08"
        rpy="0 0 0" />
      <mass
        value="0.037564" />
      <inertia
        ixx="4.052E-06"
        ixy="-2.2876E-19"
        ixz="-8.3037E-12"
        iyy="7.4131E-05"
        iyz="-3.5428E-22"
        izz="7.333E-05" />
    </inertial>
    <visual>
      <origin
        xyz="0 0 0"
        rpy="0 0 0" />
      <geometry>
        <mesh
          filename="package://landing_leg/meshes/link4.STL" />
      </geometry>
      <material
        name="">
        <color
          rgba="0.79216 0.81961 0.93333 1" />
      </material>
    </visual>
    <collision>
      <origin
        xyz="0 0 0"
        rpy="0 0 0" />
      <geometry>
        <mesh
          filename="package://landing_leg/meshes/link4.STL" />
      </geometry>
    </collision>
  </link>
  <joint
    name="joint4"
    type="revolute">
    <origin
      xyz="-0.129 -0.0245 -0.093"
      rpy="0 0 0" />
    <parent
      link="base_link" />
    <child
      link="link4" />
    <axis
      xyz="0 -1 0" />
    <limit
      lower="-3"
      upper="3"
      effort="10"
      velocity="10" />
  </joint>
  <link
    name="link4_1">
    <inertial>
      <origin
        xyz="-4.996E-16 0.0080618 -2.498E-16"
        rpy="0 0 0" />
      <mass
        value="0.01515" />
      <inertia
        ixx="5.9484E-07"
        ixy="-3.2887E-21"
        ixz="-3.6442E-08"
        iyy="1.5658E-06"
        iyz="-2.4771E-22"
        izz="1.6371E-06" />
    </inertial>
    <visual>
      <origin
        xyz="0 0 0"
        rpy="0 0 0" />
      <geometry>
        <mesh
          filename="package://landing_leg/meshes/link4_1.STL" />
      </geometry>
      <material
        name="">
        <color
          rgba="0.79216 0.81961 0.93333 1" />
      </material>
    </visual>
    <collision>
      <origin
        xyz="0 0 0"
        rpy="0 0 0" />
      <geometry>
        <mesh
          filename="package://landing_leg/meshes/link4_1.STL" />
      </geometry>
    </collision>
  </link>
  <joint
    name="joint4_1"
    type="revolute">
    <origin
      xyz="-0.229 0.016 0"
      rpy="0 0 0" />
    <parent
      link="link4" />
    <child
      link="link4_1" />
    <axis
      xyz="0 -1 0" />
    <limit
      lower="-5"
      upper="5"
      effort="10"
      velocity="10" />
  </joint>
</robot>